2023-08-29 23:27:31,877 - my_logger - ERROR - This is an error message
2023-08-29 23:27:31,879 - my_logger - CRITICAL - This is a critical message
2023-08-29 23:28:59,120 - my_logger - ERROR - This is an error message
2023-08-29 23:28:59,120 - my_logger - ERROR - This is an error message
2023-08-29 23:28:59,124 - my_logger - CRITICAL - This is a critical message
2023-08-29 23:28:59,124 - my_logger - CRITICAL - This is a critical message
2023-08-29 23:32:47,189 - my_logger - ERROR - This is an error message
2023-08-29 23:32:47,189 - my_logger - CRITICAL - This is a critical message
2023-08-29 23:43:22,215 - my_logger - ERROR - This is an error message
2023-08-29 23:43:22,215 - my_logger - ERROR - This is an error message
2023-08-29 23:43:22,220 - my_logger - CRITICAL - This is a critical message
2023-08-29 23:43:22,220 - my_logger - CRITICAL - This is a critical message
2023-08-29 23:44:54,863 - my_logger - ERROR - This is an error message
2023-08-29 23:44:54,863 - my_logger - ERROR - This is an error message
2023-08-29 23:44:54,863 - my_logger - ERROR - This is an error message
2023-08-29 23:44:54,866 - my_logger - CRITICAL - This is a critical message
2023-08-29 23:44:54,866 - my_logger - CRITICAL - This is a critical message
2023-08-29 23:44:54,866 - my_logger - CRITICAL - This is a critical message
2023-08-29 23:48:44,101 - my_logger - ERROR - Error occurred during 'do_something' function.
Traceback (most recent call last):
  File "C:\Users\Suraj\AppData\Local\Temp\ipykernel_37836\1588697528.py", line 11, in do_something
    result = 10 / 0  # Trigger a ZeroDivisionError for demonstration
ZeroDivisionError: division by zero
2023-08-29 23:48:44,101 - my_logger - ERROR - Error occurred during 'do_something' function.
Traceback (most recent call last):
  File "C:\Users\Suraj\AppData\Local\Temp\ipykernel_37836\1588697528.py", line 11, in do_something
    result = 10 / 0  # Trigger a ZeroDivisionError for demonstration
ZeroDivisionError: division by zero
2023-08-29 23:48:44,101 - my_logger - ERROR - Error occurred during 'do_something' function.
Traceback (most recent call last):
  File "C:\Users\Suraj\AppData\Local\Temp\ipykernel_37836\1588697528.py", line 11, in do_something
    result = 10 / 0  # Trigger a ZeroDivisionError for demonstration
ZeroDivisionError: division by zero
